Workbook

Sheet Planilha1
P1: ='Análise'!C13 -> 202601 | Q1: ='Análise'!D13 -> 202602 | R1: ='Análise'!E13 -> 202603 | S1: ='Análise'!F13 -> 202604 | T1: ='Análise'!G13 -> 202605 | U1: ='Análise'!H13 -> 202606 | V1: ='Análise'!I13 -> 202607 | W1: ='Análise'!J13 -> 202608 | ... AA1: ='Análise'!N13 -> 202612
B2: =Cadastros!B11 -> Renan Guerra/Chroma | C2: E | D2: =SUM('Análise'!C29:N29) -> 0 | F2: JAN | G2: 1 | I2: Ano | P2: ='Análise'!C14 -> JAN/2026 | Q2: ='Análise'!D14 -> FEV/2026 | R2: ='Análise'!E14 -> MAR/2026 | S2: ='Análise'!F14 -> ABR/2026 | T2: ='Análise'!G14 -> MAI/2026 | U2: ='Análise'!H14 -> JUN/2026 | V2: ='Análise'!I14 -> JUL/2026 | W2: ='Análise'!J14 -> AGO/2026 | ... AA2: ='Análise'!N14 -> DEZ/2026
B3: =Cadastros!B12 -> Amattheis | C3: E | D3: =SUM('Análise'!C30:N30) -> 350 | F3: FEV | G3: 2 | I3: 2023 | L3: Pago | O3: ='Gráficos'!E44 -> Eucomm Racing | P3: =SUMIFS('Lançamentos'!$H$5:$H$538,'Lançamentos'!$D$5:$D$538,$O$3,'Lançamentos'!$C$5:$C$538,P1) -> 0 | Q3: =SUMIFS('Lançamentos'!$H$5:$H$538,'Lançamentos'!$D$5:$D$538,$O$3,'Lançamentos'!$C$5:$C$538,Q1) -> 0 | R3: =SUMIFS('Lançamentos'!$H$5:$H$538,'Lançamentos'!$D$5:$D$538,$O$3,'Lançamentos'!$C$5:$C$538,R1) -> 0 | S3: =SUMIFS('Lançamentos'!$H$5:$H$538,'Lançamentos'!$D$5:$D$538,$O$3,'Lançamentos'!$C$5:$C$538,S1) -> 0 | T3: =SUMIFS('Lançamentos'!$H$5:$H$538,'Lançamentos'!$D$5:$D$538,$O$3,'Lançamentos'!$C$5:$C$538,T1) -> 0 | U3: =SUMIFS('Lançamentos'!$H$5:$H$538,'Lançamentos'!$D$5:$D$538,$O$3,'Lançamentos'!$C$5:$C$538,U1) -> 2500 | V3: =SUMIFS('Lançamentos'!$H$5:$H$538,'Lançamentos'!$D$5:$D$538,$O$3,'Lançamentos'!$C$5:$C$538,V1) -> 2500 | W3: =SUMIFS('Lançamentos'!$H$5:$H$538,'Lançamentos'!$D$5:$D$538,$O$3,'Lançamentos'!$C$5:$C$538,W1) -> 3700 | ... AA3: =SUMIFS('Lançamentos'!$H$5:$H$538,'Lançamentos'!$D$5:$D$538,$O$3,'Lançamentos'!$C$5:$C$538,AA1) -> 0
B4: =Cadastros!B13 -> Amattheis Vogel | C4: E | D4: =SUM('Análise'!C31:N31) -> 1000 | F4: MAR | G4: 3 | I4: 2024 | L4: Em aberto
B5: =Cadastros!B14 -> Eucomm Racing | C5: E | D5: =SUM('Análise'!C32:N32) -> 148 | F5: ABR | G5: 4 | I5: 2025 | L5: Todos
B6: =Cadastros!B15 -> CFA | C6: E | D6: =SUM('Análise'!C33:N33) -> 5500 | F6: MAI | G6: 5 | I6: 2026
B7: =Cadastros!B16 -> Kaka Magno | C7: E | D7: =SUM('Análise'!C34:N34) -> 87260.4 | F7: JUN | G7: 6 | I7: 2027
B8: =Cadastros!B17 -> Cadu Campos | C8: E | D8: =SUM('Análise'!C35:N35) -> 55850 | F8: JUL | G8: 7 | I8: 2028
B9: =Cadastros!B18 -> Piloto TN - Paulo Maia | C9: E | D9: =SUM('Análise'!C36:N36) -> 300.05 | F9: AGO | G9: 8 | I9: 2029
B10: =Cadastros!B19 -> Equipe TN - Porthack | C10: E | D10: =SUM('Análise'!C37:N37) -> 2420 | F10: SET | G10: 9
B11: =Cadastros!B20 -> Hublub | C11: E | D11: =SUM('Análise'!C38:N38) -> 7200 | F11: OUT | G11: 10
B12: =Cadastros!B21 -> Silvana (Freela) | C12: E | D12: =SUM('Análise'!C39:N39) -> 0 | F12: NOV | G12: 11
B13: =Cadastros!B22 -> Helio Castroneves | C13: E | D13: =SUM('Análise'!C40:N40) -> 7035.18 | F13: DEZ | G13: 12
B14: =Cadastros!B23 -> Freela Silas Passos | C14: E | D14: =SUM('Análise'!C41:N41) -> 3111.2
B15: =Cadastros!B24 -> Freela (Elleven) | C15: E | D15: =SUM('Análise'!C42:N42) -> 0
B16: =Cadastros!B25 -> SAE Brasil | C16: E | D16: =SUM('Análise'!C43:N43) -> 705.82
B17: =Cadastros!B26 -> Entrada reembolso | C17: E | D17: =SUM('Análise'!C44:N44) -> 0
B18: =Cadastros!B28 -> RMattheis | C18: E | D18: =SUM('Análise'!C45:N45) -> 2389.64
B19: =Cadastros!C11 -> Salário Sócias | C19: S | D19: =SUM('Análise'!C46:N46) -> 4786.7
B20: =Cadastros!C12 -> Locomoção etapas/Uber | C20: S | D20: =SUM('Análise'!C47:N47) -> 2710.31
B21: =Cadastros!C13 -> Designer | C21: S | D21: =SUM('Análise'!C48:N48) -> 206.4
B22: =Cadastros!C14 -> Poupança - meses sem corrida | C22: S | D22: =SUM('Análise'!C49:N49) -> 0
B23: =Cadastros!C15 -> Impostos | C23: S | D23: =SUM('Análise'!C50:N50) -> 373
B24: =Cadastros!C16 -> Pagamento Freelas | C24: S | D24: =SUM('Análise'!C51:N51) -> 172.1
B25: =Cadastros!C17 -> Reembolso sócias | C25: S | D25: =SUM('Análise'!C52:N52) -> 17988.6
B26: =Cadastros!C18 -> Contador | C26: S | D26: =SUM('Análise'!C53:N53) -> 26099.79
B27: =Cadastros!C19 -> Uniforme | C27: S | D27: =SUM('Análise'!C54:N54) -> 0
B28: =Cadastros!C20 -> Fotos/Estúdio | C28: S | D28: =SUM('Análise'!C55:N55) -> 0
B29: =Cadastros!C21 -> Hospedagem | C29: S | D29: =SUM('Análise'!C56:N56) -> 0
B30: =Cadastros!C22 -> Avião/ônibus etapas | C30: S | D30: =SUM('Análise'!C57:N57) -> 0
... B34: =Cadastros!C26 -> DAS Marina | C34: S | D34: =SUM('Análise'!C61:N61) -> 0
B35: =Cadastros!C28 -> DAS Victoria | C35: S | D35: =SUM('Análise'!C62:N62) -> 0

Sheet Clientes
A1: CLIENTES | B1: VALOR CONTRATO | C1: DATA VIGENCIA | D1: STATUS | E1: TIPO SERVIÇO | F1: CONTATO RESPONSÁVEL
A2: Amattheis | B2: R$ 2.500,00 | C2: 46042 | D2: Ativo | E2: Gestão de Mídias | F2: Rachel
A3: AmattheisVogel | B3: R$ 5.500,00 | C3: 46055 | D3: Ativo | E3: Gestão de Mídias | F3: Sabrina
A4: Kaka Magno | B4: R$ 1.200,00 | C4: 46055 | D4: Ativo | E4: Cobertura Real Time | F4: Kaka
A5: Eucomm Racing | B5: R$ 2.500,00 | C5: 46055 | D5: Ativo | E5: Cobertura Real Time | F5: Fabio
A6: Renan Guerra | B6: R$ 1.200,00 | C6: 46203 | D6: Ativo | E6: Cobertura Real Time | F6: Kati
A7: Porthack | B7: R$ 1.800,00 | C7: 46447 | D7: Ativo | E7: Cobertura Real Time | F7: [URL]
A8: Cadu | B8: R$ 2.100,00 | C8: 46152 | D8: Ativo | E8: Cobertura Real Time | F8: [URL]
A9: Piloto 1 TN | B9: R$ 1.800,00 | C9: 45992 | D9: Ativo | E9: Cobertura Real Time | F9: [URL]
A10: CFA | B10: R$1.066,00 | C10: 46041 | D10: Ativo | E10: Gestão de Mídias | F10: Rachel Loh
A11: Meli Racing/HubLub | B11: R$4.600,00 | C11: 46045 | D11: Ativo | F11: Beto
A12: Frella Silvana

Sheet Dados Cadastrais Clientes
A1: Razão Social | B1: CNPJ | C1: Endereço | D1: Telefone | E1: Insc Estaudal | F1: Insc Municipal
A2: HUB-LUB LIVE MARKETING LTDA | B2: 10.492.925/0001-50 | C2: Av. Roque Petroni Junior, 1089 – 7.o andar sala. 914 Centro Profissional Morumbi Shopping 04707-900 São Paulo-SP | E2: 142318250110 | F2: 3.848.395-5 | G2: 4600
A3: PY2 RADIOSOM INSTALACOES, COMERCIO, IMPORTACAO E EXPORTACAO EIRELI | B3: 11.061.010/0001-53 | C3: R DO IMPERADOR, 250, 02.074-000 - Vila Paiva - São Paulo - SP
A4: VOGEL-RENNENPREPARACAODEVEICULOSDECOMPETICAOLTDA | B4: 04.388.367/0002-66 | C4: JOAO VON ZUBEN,116,CASA 03,CAPELA, Vinhedo - SP
A5: Chroma | B5: 50.491.759/0001-92 | F5: 1200
A6: Cadu e Andreia/ Inovação treinamentos e serviços ltda | B6: 07.272.403/0001-39 | F6: 1500
A7: Porthack | B7: 30.531.189/0001-00
A8: Paulo Maia
A9: RF PRODUCAO DE EVENTOS ESPORTIVOS LTDA. (AMattheis) | B9: 07.655.267/0001-66
A10: SAE Brasil | B10: 67.350.769/0001-00 | C10: Av Paulista 726. CONJ 1303 G 30
A11: RMattheis Off road /AC Preparações e operações LTDA | B11: 48.781.977/0001-10
A12: POUPANÇA: (3.600 por 5 meses - ou seja - receber 5.200 atualmente)
A14: CNPJ VIC 67.170.505/0001-75
A15: CNPJ Marina 54.501.083/0001-21

Sheet Previsão de caixa
A1: Previsão de caixa | B1: Previsão de despesas
A2: R$5.500,00 (Vogel) | B2: R$2.000,00 (Passagem)
A3: R$5.910,00 (Beto) | B3: R$ 1.160,00 (Iza)
A4: R$2.500,00 (AMM) | B4: R$ 640,00 (Ju)
A5: R$2.500,00 (Fabio) | B5: R$ 420,00 (Uber) | F5: Abril PROJETADO
A6: R$1.250,00 (Kaká) | B6: R$ 700,00 (Frela etapa) | F6: ENTRADAS | G6: SAÍDAS
A7: R$ 1.200,00 (Renan) | B7: - (Videomarker) | F7: R$5.500,00 (Vogel) | G7: R$423,49 (Curvelo)
A8: R$1.066,00 (CBA) | B8: R$459,00 (Uniforme) | F8: R$5.910,00 (Beto) | G8: R$ 1.160,00 (Iza)
A9: R$2.100 (Porthack) | B9: R$ 1.050 (Bia Martins) | F9: R$2.500,00 (AMM) | G9: R$ 640,00 (Ju)
A10: Total: R$ 19.926,00 | B10: R$ 4920,00 | F10: R$2.500,00 (Fabio) | G10: R$ 420,00 (Uber)
F11: R$2.100,00 (Blau) | G11: R$459,00 (Uniforme)
A12: Salário sócias: R$7.503,00 | F12: R$ 1.200,00 (Renan) | G12: R$1638,84 (Ida oficina hotel passagens)
F13: R$3.198,00 (CBA) | G13: R$ 263,23 (ida sp e volta sp)
F14: R$2.100,00 (Porthack) | G14: R$1211,97 Cuiabá marina
G15: R$ 1075,96 cuiaba victoria
A16: ENTRADAS | B16: SAÍDAS | G16: R$ 1.149,00 (Dani)
A17: R$2.500,00 (Fabio) | B17: R$640,00 (ju) | G17: R$1.050 (Bia)
A18: R$2.500,00 (AMM) | B18: R$160,00 | F18: R$ 25.008 | G18: R$ 9.490,99 | H18: Caixa 15.517,01 | I18: Caixa: 3.000,00
A19: R$4.600,00 (Hublub) | I19: Salário: 6.258,00
A20: R$6.000,00 (Vogel) | H20: 5K cada uma*
A21: R$1.250,00 (Kaká) | F21: ABRIL REAL
A22: Previsão | F22: ENTRADAS | G22: SAÍDAS
A23: R$2.500,00 (AMM) | F23: R$5.500,00 (Vogel) | G23: R$423,49 (Curvelo)
A24: R$1.500 (Andreia) | F24: R$5.910,00 (Beto) | G24: R$ 1.160,00 (Iza)
F25: R$2.500,00 (AMM) | G25: R$1211,97 (Cuiabá Marina)
A26: Dia 20/06 | F26: R$2.500,00 (Fabio) | G26: R$1075,96 (Cuiabá Victoria)
F27: R$2.100,00 (Blau) | G27: R$ 1.000,00 (Dani)
A28: Temos hoje: R$11.902 | F28: R$ 1.200,00 (Renan) | G28: R$1.050 (Bia)
A29: R$1.500 (Andreia) | B29: R$4.651 (Freela Cuiabá) | F29: R$3.198,00 (CBA) | G29: R$ 100 (Marina ida SP)
A30: R$2.500 (amattheis) | F30: R$2.100,00 (Porthack) | G30: R$ 509,74 (Ida petrópolis)
A31: R$1.066 (cba) | G31: R$ 456 (Hotel petrópolis)
G32: 900 (Ida e Volta Goiânia) Vic
A33: R$16.968 | B33: R$4.651 | C33: 12317 | G33: R$ 85,00 (Das Mei)
F34: R$ 25.008 | G34: R$209,02 (Uniforme Vic)
A35: 3720 | B35: Marina | G35: R$ 250(Uniforme Marina)
A36: 7600 | B36: Victoria | G36: R$200 (Despesa Hotel)
G37: R$100 (Volta SP Marina)
G38: R$ 640,00 (Ju)
A39: Cixa - R$582,00
G40: R$ 9.371,00
...

Sheet Lançamentos
B4: Data | C4: Id | D4: Plano de Conta | E4: Coluna1 | F4: Valor | G4: Pago | H4: Valor_analise
B5: 46041 | C5: =IF('Lançamentos'!$B5<>"",YEAR('Lançamentos'!$B5)*100+MONTH(B5),"") -> 202601 | D5: Uniforme | E5: {=IFERROR(_xlfn.XLOOKUP('Lançamentos'!$D5,Planilha1!$B$2:$B$35,Planilha1!$C$2:$C$35),0)} -> S | F5: 705.82 | G5: TRUE | H5: =IF(AND('Análise'!$G$7="Pago",'Lançamentos'!$G5=TRUE),'Lançamentos'!$F5,IF(AND('Análise'!$G$7="Em Aberto",'Lançamentos'!$G5=FALSE),'Lançamentos'!$F5,IF('Análise'!$G$7="Todos",'Lançamentos'!$F5,0))) -> 705.82
B6: 46042 | C6: =IF('Lançamentos'!$B6<>"",YEAR('Lançamentos'!$B6)*100+MONTH(B6),"") -> 202601 | D6: Amattheis | E6: {=IFERROR(_xlfn.XLOOKUP('Lançamentos'!$D6,Planilha1!$B$2:$B$35,Planilha1!$C$2:$C$35),0)} -> E | F6: 2500 | G6: TRUE | H6: =IF(AND('Análise'!$G$7="Pago",'Lançamentos'!$G6=TRUE),'Lançamentos'!$F6,IF(AND('Análise'!$G$7="Em Aberto",'Lançamentos'!$G6=FALSE),'Lançamentos'!$F6,IF('Análise'!$G$7="Todos",'Lançamentos'!$F6,0))) -> 2500
B7: 45306 | C7: =IF('Lançamentos'!$B7<>"",YEAR('Lançamentos'!$B7)*100+MONTH(B7),"") -> 202401 | D7: Fotos/Estúdio | E7: {=IFERROR(_xlfn.XLOOKUP('Lançamentos'!$D7,Planilha1!$B$2:$B$35,Planilha1!$C$2:$C$35),0)} -> S | F7: 650 | G7: TRUE | H7: =IF(AND('Análise'!$G$7="Pago",'Lançamentos'!$G7=TRUE),'Lançamentos'!$F7,IF(AND('Análise'!$G$7="Em Aberto",'Lançamentos'!$G7=FALSE),'Lançamentos'!$F7,IF('Análise'!$G$7="Todos",'Lançamentos'!$F7,0))) -> 650
B8: 46064 | C8: =IF('Lançamentos'!$B8<>"",YEAR('Lançamentos'!$B8)*100+MONTH(B8),"") -> 202602 | D8: Silvana (Freela) | E8: {=IFERROR(_xlfn.XLOOKUP('Lançamentos'!$D8,Planilha1!$B$2:$B$35,Planilha1!$C$2:$C$35),0)} -> E | F8: 500 | G8: TRUE | H8: =IF(AND('Análise'!$G$7="Pago",'Lançamentos'!$G8=TRUE),'Lançamentos'!$F8,IF(AND('Análise'!$G$7="Em Aberto",'Lançamentos'!$G8=FALSE),'Lançamentos'!$F8,IF('Análise'!$G$7="Todos",'Lançamentos'!$F8,0))) -> 500
B9: 46086 | C9: =IF('Lançamentos'!$B9<>"",YEAR('Lançamentos'!$B9)*100+MONTH(B9),"") -> 202603 | D9: Hospedagem | E9: {=IFERROR(_xlfn.XLOOKUP('Lançamentos'!$D9,Planilha1!$B$2:$B$35,Planilha1!$C$2:$C$35),0)} -> S | F9: 1128 | G9: TRUE | H9: =IF(AND('Análise'!$G$7="Pago",'Lançamentos'!$G9=TRUE),'Lançamentos'!$F9,IF(AND('Análise'!$G$7="Em Aberto",'Lançamentos'!$G9=FALSE),'Lançamentos'!$F9,IF('Análise'!$G$7="Todos",'Lançamentos'!$F9,0))) -> 1128
B10: 46086 | C10: =IF('Lançamentos'!$B10<>"",YEAR('Lançamentos'!$B10)*100+MONTH(B10),"") -> 202603 | D10: Avião/ônibus etapas | E10: {=IFERROR(_xlfn.XLOOKUP('Lançamentos'!$D10,Planilha1!$B$2:$B$35,Planilha1!$C$2:$C$35),0)} -> S | F10: 1598 | G10: TRUE | H10: =IF(AND('Análise'!$G$7="Pago",'Lançamentos'!$G10=TRUE),'Lançamentos'!$F10,IF(AND('Análise'!$G$7="Em Aberto",'Lançamentos'!$G10=FALSE),'Lançamentos'!$F10,IF('Análise'!$G$7="Todos",'Lançamentos'!$F10,0))) -> 1598
B11: 46073 | C11: =IF('Lançamentos'!$B11<>"",YEAR('Lançamentos'!$B11)*100+MONTH(B11),"") -> 202602 | D11: Amattheis | E11: {=IFERROR(_xlfn.XLOOKUP('Lançamentos'!$D11,Planilha1!$B$2:$B$35,Planilha1!$C$2:$C$35),0)} -> E | F11: 2500 | G11: TRUE | H11: =IF(AND('Análise'!$G$7="Pago",'Lançamentos'!$G11=TRUE),'Lançamentos'!$F11,IF(AND('Análise'!$G$7="Em Aberto",'Lançamentos'!$G11=FALSE),'Lançamentos'!$F11,IF('Análise'!$G$7="Todos",'Lançamentos'!$F11,0))) -> 2500
B12: 45306 | C12: =IF('Lançamentos'!$B12<>"",YEAR('Lançamentos'!$B12)*100+MONTH(B12),"") -> 202401 | D12: Pagamento Freelas | E12: {=IFERROR(_xlfn.XLOOKUP('Lançamentos'!$D12,Planilha1!$B$2:$B$35,Planilha1!$C$2:$C$35),0)} -> S | F12: 140 | G12: TRUE | H12: =IF(AND('Análise'!$G$7="Pago",'Lançamentos'!$G12=TRUE),'Lançamentos'!$F12,IF(AND('Análise'!$G$7="Em Aberto",'Lançamentos'!$G12=FALSE),'Lançamentos'!$F12,IF('Análise'!$G$7="Todos",'Lançamentos'!$F12,0))) -> 140
B13: 46205 | C13: =IF('Lançamentos'!$B13<>"",YEAR('Lançamentos'!$B13)*100+MONTH(B13),"") -> 202607 | D13: Piloto TN - Paulo Maia | E13: {=IFERROR(_xlfn.XLOOKUP('Lançamentos'!$D13,Planilha1!$B$2:$B$35,Planilha1!$C$2:$C$35),0)} -> E | F13: 3600 | G13: TRUE | H13: =IF(AND('Análise'!$G$7="Pago",'Lançamentos'!$G13=TRUE),'Lançamentos'!$F13,IF(AND('Análise'!$G$7="Em Aberto",'Lançamentos'!$G13=FALSE),'Lançamentos'!$F13,IF('Análise'!$G$7="Todos",'Lançamentos'!$F13,0))) -> 3600
B14: 46205 | C14: =IF('Lançamentos'!$B14<>"",YEAR('Lançamentos'!$B14)*100+MONTH(B14),"") -> 202607 | D14: Eucomm Racing | E14: {=IFERROR(_xlfn.XLOOKUP('Lançamentos'!$D14,Planilha1!$B$2:$B$35,Planilha1!$C$2:$C$35),0)} -> E | F14: 2500 | G14: TRUE | H14: =IF(AND('Análise'!$G$7="Pago",'Lançamentos'!$G14=TRUE),'Lançamentos'!$F14,IF(AND('Análise'!$G$7="Em Aberto",'Lançamentos'!$G14=FALSE),'Lançamentos'!$F14,IF('Análise'!$G$7="Todos",'Lançamentos'!$F14,0))) -> 2500
B15: 46204 | C15: =IF('Lançamentos'!$B15<>"",YEAR('Lançamentos'!$B15)*100+MONTH(B15),"") -> 202607 | D15: CFA | E15: {=IFERROR(_xlfn.XLOOKUP('Lançamentos'!$D15,Planilha1!$B$2:$B$35,Planilha1!$C$2:$C$35),0)} -> E | F15: 1066 | G15: TRUE | H15: =IF(AND('Análise'!$G$7="Pago",'Lançamentos'!$G15=TRUE),'Lançamentos'!$F15,IF(AND('Análise'!$G$7="Em Aberto",'Lançamentos'!$G15=FALSE),'Lançamentos'!$F15,IF('Análise'!$G$7="Todos",'Lançamentos'!$F15,0))) -> 1066
B16: 46204 | C16: =IF('Lançamentos'!$B16<>"",YEAR('Lançamentos'!$B16)*100+MONTH(B16),"") -> 202607 | D16: Equipe TN - Porthack | E16: {=IFERROR(_xlfn.XLOOKUP('Lançamentos'!$D16,Planilha1!$B$2:$B$35,Planilha1!$C$2:$C$35),0)} -> E | F16: 1800 | G16: TRUE | H16: =IF(AND('Análise'!$G$7="Pago",'Lançamentos'!$G16=TRUE),'Lançamentos'!$F16,IF(AND('Análise'!$G$7="Em Aberto",'Lançamentos'!$G16=FALSE),'Lançamentos'!$F16,IF('Análise'!$G$7="Todos",'Lançamentos'!$F16,0))) -> 1800
... B124: 46274 | C124: =IF('Lançamentos'!$B124<>"",YEAR('Lançamentos'!$B124)*100+MONTH(B124),"") -> 202609 | D124: DAS Marina | E124: {=IFERROR(_xlfn.XLOOKUP('Lançamentos'!$D124,Planilha1!$B$2:$B$35,Planilha1!$C$2:$C$35),0)} -> S | F124: 199 | G124: FALSE | H124: =IF(AND('Análise'!$G$7="Pago",'Lançamentos'!$G124=TRUE),'Lançamentos'!$F124,IF(AND('Análise'!$G$7="Em Aberto",'Lançamentos'!$G124=FALSE),'Lançamentos'!$F124,IF('Análise'!$G$7="Todos",'Lançamentos'!$F124,0))) -> 199
C125: =IF('Lançamentos'!$B125<>"",YEAR('Lançamentos'!$B125)*100+MONTH(B125),"") | E125: {=IFERROR(_xlfn.XLOOKUP('Lançamentos'!$D125,Planilha1!$B$2:$B$35,Planilha1!$C$2:$C$35),0)} -> 0 | G125: FALSE | H125: =IF(AND('Análise'!$G$7="Pago",'Lançamentos'!$G125=TRUE),'Lançamentos'!$F125,IF(AND('Análise'!$G$7="Em Aberto",'Lançamentos'!$G125=FALSE),'Lançamentos'!$F125,IF('Análise'!$G$7="Todos",'Lançamentos'!$F125,0)))
C126: =IF('Lançamentos'!$B126<>"",YEAR('Lançamentos'!$B126)*100+MONTH(B126),"") | E126: {=IFERROR(_xlfn.XLOOKUP('Lançamentos'!$D126,Planilha1!$B$2:$B$35,Planilha1!$C$2:$C$35),0)} -> 0 | G126: FALSE | H126: =IF(AND('Análise'!$G$7="Pago",'Lançamentos'!$G126=TRUE),'Lançamentos'!$F126,IF(AND('Análise'!$G$7="Em Aberto",'Lançamentos'!$G126=FALSE),'Lançamentos'!$F126,IF('Análise'!$G$7="Todos",'Lançamentos'!$F126,0)))
C127: =IF('Lançamentos'!$B127<>"",YEAR('Lançamentos'!$B127)*100+MONTH(B127),"") | E127: {=IFERROR(_xlfn.XLOOKUP('Lançamentos'!$D127,Planilha1!$B$2:$B$35,Planilha1!$C$2:$C$35),0)} -> 0 | G127: FALSE | H127: =IF(AND('Análise'!$G$7="Pago",'Lançamentos'!$G127=TRUE),'Lançamentos'!$F127,IF(AND('Análise'!$G$7="Em Aberto",'Lançamentos'!$G127=FALSE),'Lançamentos'!$F127,IF('Análise'!$G$7="Todos",'Lançamentos'!$F127,0)))
C128: =IF('Lançamentos'!$B128<>"",YEAR('Lançamentos'!$B128)*100+MONTH(B128),"") | E128: {=IFERROR(_xlfn.XLOOKUP('Lançamentos'!$D128,Planilha1!$B$2:$B$35,Planilha1!$C$2:$C$35),0)} -> 0 | G128: FALSE | H128: =IF(AND('Análise'!$G$7="Pago",'Lançamentos'!$G128=TRUE),'Lançamentos'!$F128,IF(AND('Análise'!$G$7="Em Aberto",'Lançamentos'!$G128=FALSE),'Lançamentos'!$F128,IF('Análise'!$G$7="Todos",'Lançamentos'!$F128,0)))
C129: =IF('Lançamentos'!$B129<>"",YEAR('Lançamentos'!$B129)*100+MONTH(B129),"") | E129: {=IFERROR(_xlfn.XLOOKUP('Lançamentos'!$D129,Planilha1!$B$2:$B$35,Planilha1!$C$2:$C$35),0)} -> 0 | G129: FALSE | H129: =IF(AND('Análise'!$G$7="Pago",'Lançamentos'!$G129=TRUE),'Lançamentos'!$F129,IF(AND('Análise'!$G$7="Em Aberto",'Lançamentos'!$G129=FALSE),'Lançamentos'!$F129,IF('Análise'!$G$7="Todos",'Lançamentos'!$F129,0)))
C130: =IF('Lançamentos'!$B130<>"",YEAR('Lançamentos'!$B130)*100+MONTH(B130),"") | E130: {=IFERROR(_xlfn.XLOOKUP('Lançamentos'!$D130,Planilha1!$B$2:$B$35,Planilha1!$C$2:$C$35),0)} -> 0 | G130: FALSE | H130: =IF(AND('Análise'!$G$7="Pago",'Lançamentos'!$G130=TRUE),'Lançamentos'!$F130,IF(AND('Análise'!$G$7="Em Aberto",'Lançamentos'!$G130=FALSE),'Lançamentos'!$F130,IF('Análise'!$G$7="Todos",'Lançamentos'!$F130,0)))
C131: =IF('Lançamentos'!$B131<>"",YEAR('Lançamentos'!$B131)*100+MONTH(B131),"") | E131: {=IFERROR(_xlfn.XLOOKUP('Lançamentos'!$D131,Planilha1!$B$2:$B$35,Planilha1!$C$2:$C$35),0)} -> 0 | G131: FALSE | H131: =IF(AND('Análise'!$G$7="Pago",'Lançamentos'!$G131=TRUE),'Lançamentos'!$F131,IF(AND('Análise'!$G$7="Em Aberto",'Lançamentos'!$G131=FALSE),'Lançamentos'!$F131,IF('Análise'!$G$7="Todos",'Lançamentos'!$F131,0)))
C132: =IF('Lançamentos'!$B132<>"",YEAR('Lançamentos'!$B132)*100+MONTH(B132),"") | E132: {=IFERROR(_xlfn.XLOOKUP('Lançamentos'!$D132,Planilha1!$B$2:$B$35,Planilha1!$C$2:$C$35),0)} -> 0 | G132: FALSE | H132: =IF(AND('Análise'!$G$7="Pago",'Lançamentos'!$G132=TRUE),'Lançamentos'!$F132,IF(AND('Análise'!$G$7="Em Aberto",'Lançamentos'!$G132=FALSE),'Lançamentos'!$F132,IF('Análise'!$G$7="Todos",'Lançamentos'!$F132,0)))
C133: =IF('Lançamentos'!$B133<>"",YEAR('Lançamentos'!$B133)*100+MONTH(B133),"") | E133: {=IFERROR(_xlfn.XLOOKUP('Lançamentos'!$D133,Planilha1!$B$2:$B$35,Planilha1!$C$2:$C$35),0)} -> 0 | G133: FALSE | H133: =IF(AND('Análise'!$G$7="Pago",'Lançamentos'!$G133=TRUE),'Lançamentos'!$F133,IF(AND('Análise'!$G$7="Em Aberto",'Lançamentos'!$G133=FALSE),'Lançamentos'!$F133,IF('Análise'!$G$7="Todos",'Lançamentos'!$F133,0)))
C134: =IF('Lançamentos'!$B134<>"",YEAR('Lançamentos'!$B134)*100+MONTH(B134),"") | E134: {=IFERROR(_xlfn.XLOOKUP('Lançamentos'!$D134,Planilha1!$B$2:$B$35,Planilha1!$C$2:$C$35),0)} -> 0 | G134: FALSE | H134: =IF(AND('Análise'!$G$7="Pago",'Lançamentos'!$G134=TRUE),'Lançamentos'!$F134,IF(AND('Análise'!$G$7="Em Aberto",'Lançamentos'!$G134=FALSE),'Lançamentos'!$F134,IF('Análise'!$G$7="Todos",'Lançamentos'!$F134,0)))
C135: =IF('Lançamentos'!$B135<>"",YEAR('Lançamentos'!$B135)*100+MONTH(B135),"") | E135: {=IFERROR(_xlfn.XLOOKUP('Lançamentos'!$D135,Planilha1!$B$2:$B$35,Planilha1!$C$2:$C$35),0)} -> 0 | G135: FALSE | H135: =IF(AND('Análise'!$G$7="Pago",'Lançamentos'!$G135=TRUE),'Lançamentos'!$F135,IF(AND('Análise'!$G$7="Em Aberto",'Lançamentos'!$G135=FALSE),'Lançamentos'!$F135,IF('Análise'!$G$7="Todos",'Lançamentos'!$F135,0)))
C136: =IF('Lançamentos'!$B136<>"",YEAR('Lançamentos'!$B136)*100+MONTH(B136),"") | E136: {=IFERROR(_xlfn.XLOOKUP('Lançamentos'!$D136,Planilha1!$B$2:$B$35,Planilha1!$C$2:$C$35),0)} -> 0 | G136: FALSE | H136: =IF(AND('Análise'!$G$7="Pago",'Lançamentos'!$G136=TRUE),'Lançamentos'!$F136,IF(AND('Análise'!$G$7="Em Aberto",'Lançamentos'!$G136=FALSE),'Lançamentos'!$F136,IF('Análise'!$G$7="Todos",'Lançamentos'!$F136,0)))
... C538: =IF('Lançamentos'!$B538<>"",YEAR('Lançamentos'!$B538)*100+MONTH(B538),"") | E538: {=IFERROR(_xlfn.XLOOKUP('Lançamentos'!$D538,Planilha1!$B$2:$B$35,Planilha1!$C$2:$C$35),0)} -> 0 | G538: FALSE | H538: =IF(AND('Análise'!$G$7="Pago",'Lançamentos'!$G538=TRUE),'Lançamentos'!$F538,IF(AND('Análise'!$G$7="Em Aberto",'Lançamentos'!$G538=FALSE),'Lançamentos'!$F538,IF('Análise'!$G$7="Todos",'Lançamentos'!$F538,0)))

Sheet Cadastros
B5: Empresa: | C5: Trackside Media
B8: Plano de Contas
B10: Entradas | C10: Saídas
B11: Renan Guerra/Chroma | C11: Salário Sócias
B12: Amattheis | C12: Locomoção etapas/Uber
B13: Amattheis Vogel | C13: Designer
B14: Eucomm Racing | C14: Poupança - meses sem corrida
B15: CFA | C15: Impostos
B16: Kaka Magno | C16: Pagamento Freelas
B17: Cadu Campos | C17: Reembolso sócias
B18: Piloto TN - Paulo Maia | C18: Contador
B19: Equipe TN - Porthack | C19: Uniforme
B20: Hublub | C20: Fotos/Estúdio
B21: Silvana (Freela) | C21: Hospedagem
... B26: Entrada reembolso | C26: DAS Marina
B27: ENTRADA BATER CAIXA
B28: RMattheis | C28: DAS Victoria
B30: Personalize a planilha: Ajuste os nomes dos recebimentos de acordo com a sua realidade.
B31: ⚠️ Para garantir o funcionamento, não acrescente ou remova linhas.

Sheet Análise
K6: 9
B7: Selecione o primeiro mês | C7: JAN | E7: Status Pagamento | G7: Todos | I7: \
B8: Selecione o ano | C8: 2026 | E8: Saldo Incial Caixa | G8: 0
B10: ⚠️ Para garantir o funcionamento, não acrescente ou remova linhas.
C11: {=_xlfn.XLOOKUP(C7,Planilha1!$F$2:$F$13,Planilha1!$G$2:$G$13)} -> 1 | D11: =IF(C11=12,1,C11+1) -> 2 | E11: =IF(D11=12,1,D11+1) -> 3 | F11: =IF(E11=12,1,E11+1) -> 4 | G11: =IF(F11=12,1,F11+1) -> 5 | H11: =IF(G11=12,1,G11+1) -> 6 | I11: =IF(H11=12,1,H11+1) -> 7 | J11: =IF(I11=12,1,I11+1) -> 8 | K11: =IF(J11=12,1,J11+1) -> 9 | ... U11: =IF(T11=12,1,T11+1) -> 7
C12: =C8 -> 2026 | D12: =IF(D11=1,C12+1,C12) -> 2026 | E12: =IF(E11=1,D12+1,D12) -> 2026 | F12: =IF(F11=1,E12+1,E12) -> 2026 | G12: =IF(G11=1,F12+1,F12) -> 2026 | H12: =IF(H11=1,G12+1,G12) -> 2026 | I12: =IF(I11=1,H12+1,H12) -> 2026 | J12: =IF(J11=1,I12+1,I12) -> 2026 | K12: =IF(K11=1,J12+1,J12) -> 2026 | ... U12: =IF(U11=1,T12+1,T12) -> 2027
C13: =C12*100+C11 -> 202601 | D13: =D12*100+D11 -> 202602 | E13: =E12*100+E11 -> 202603 | F13: =F12*100+F11 -> 202604 | G13: =G12*100+G11 -> 202605 | H13: =H12*100+H11 -> 202606 | I13: =I12*100+I11 -> 202607 | J13: =J12*100+J11 -> 202608 | ... U13: =U12*100+U11 -> 202707
C14: {=_xlfn.XLOOKUP(C11,Planilha1!$G$2:$G$13,Planilha1!$F$2:$F$13)&"/"&C12} -> JAN/2026 | D14: {=_xlfn.XLOOKUP(D11,Planilha1!$G$2:$G$13,Planilha1!$F$2:$F$13)&"/"&D12} -> FEV/2026 | E14: {=_xlfn.XLOOKUP(E11,Planilha1!$G$2:$G$13,Planilha1!$F$2:$F$13)&"/"&E12} -> MAR/2026 | F14: {=_xlfn.XLOOKUP(F11,Planilha1!$G$2:$G$13,Planilha1!$F$2:$F$13)&"/"&F12} -> ABR/2026 | G14: {=_xlfn.XLOOKUP(G11,Planilha1!$G$2:$G$13,Planilha1!$F$2:$F$13)&"/"&G12} -> MAI/2026 | H14: {=_xlfn.XLOOKUP(H11,Planilha1!$G$2:$G$13,Planilha1!$F$2:$F$13)&"/"&H12} -> JUN/2026 | I14: {=_xlfn.XLOOKUP(I11,Planilha1!$G$2:$G$13,Planilha1!$F$2:$F$13)&"/"&I12} -> JUL/2026 | J14: {=_xlfn.XLOOKUP(J11,Planilha1!$G$2:$G$13,Planilha1!$F$2:$F$13)&"/"&J12} -> AGO/2026 | ... U14: {=_xlfn.XLOOKUP(U11,Planilha1!$G$2:$G$13,Planilha1!$F$2:$F$13)&"/"&U12} -> JUL/2027
B15: Saldo Inicial Caixa | C15: 0 | D15: 0 | E15: =D53 -> 3000 | F15: =E53 -> 274 | I15: 606.81 | K15: =J53 -> 3082.52 | L15: =K53 -> 382.62 | M15: =L53 -> 382.62 | N15: =M53 -> 382.62 | O15: =N53 -> 382.62 | P15: =O53 -> 382.62 | Q15: =P53 -> 382.62 | R15: =Q53 -> 382.62 | ... U15: =T53 -> 382.62
B16: Entradas | C16: =SUM(C17:C33) -> 2500 | D16: =SUM(D17:D33) -> 3000 | E16: =SUM(E17:E33) -> 0 | F16: =SUM(F17:F33) -> 0 | G16: =SUM(G17:G33) -> 7166 | H16: =SUM(H17:H33) -> 21010 | I16: =SUM(I17:I33) -> 26271 | J16: =SUM(J17:J33) -> 24668 | ... U16: =SUM(U17:U33) -> 0
B17: =Planilha1!B2 -> Renan Guerra/Chroma | C17: =SUMIFS('Lançamentos'!$H$5:$H$538,'Lançamentos'!$D$5:$D$538,'Análise'!$B17,'Lançamentos'!$C$5:$C$538,'Análise'!C$13) -> 0 | D17: =SUMIFS('Lançamentos'!$H$5:$H$538,'Lançamentos'!$D$5:$D$538,'Análise'!$B17,'Lançamentos'!$C$5:$C$538,'Análise'!D$13) -> 0 | E17: =SUMIFS('Lançamentos'!$H$5:$H$538,'Lançamentos'!$D$5:$D$538,'Análise'!$B17,'Lançamentos'!$C$5:$C$538,'Análise'!E$13) -> 0 | F17: =SUMIFS('Lançamentos'!$H$5:$H$538,'Lançamentos'!$D$5:$D$538,'Análise'!$B17,'Lançamentos'!$C$5:$C$538,'Análise'!F$13) -> 0 | G17: =SUMIFS('Lançamentos'!$H$5:$H$538,'Lançamentos'!$D$5:$D$538,'Análise'!$B17,'Lançamentos'!$C$5:$C$538,'Análise'!G$13) -> 0 | H17: =SUMIFS('Lançamentos'!$H$5:$H$538,'Lançamentos'!$D$5:$D$538,'Análise'!$B17,'Lançamentos'!$C$5:$C$538,'Análise'!H$13) -> 1200 | I17: =SUMIFS('Lançamentos'!$H$5:$H$538,'Lançamentos'!$D$5:$D$538,'Análise'!$B17,'Lançamentos'!$C$5:$C$538,'Análise'!I$13) -> 1200 | J17: =SUMIFS('Lançamentos'!$H$5:$H$538,'Lançamentos'!$D$5:$D$538,'Análise'!$B17,'Lançamentos'!$C$5:$C$538,'Análise'!J$13) -> 2400 | ... P17: =SUMIFS('Lançamentos'!$H$5:$H$538,'Lançamentos'!$D$5:$D$538,'Análise'!$B17,'Lançamentos'!$C$5:$C$538,'Análise'!P$13) -> 0
B18: =Planilha1!B3 -> Amattheis | C18: =SUMIFS('Lançamentos'!$H$5:$H$538,'Lançamentos'!$D$5:$D$538,'Análise'!$B18,'Lançamentos'!$C$5:$C$538,'Análise'!C$13) -> 2500 | D18: =SUMIFS('Lançamentos'!$H$5:$H$538,'Lançamentos'!$D$5:$D$538,'Análise'!$B18,'Lançamentos'!$C$5:$C$538,'Análise'!D$13) -> 2500 | E18: =SUMIFS('Lançamentos'!$H$5:$H$538,'Lançamentos'!$D$5:$D$538,'Análise'!$B18,'Lançamentos'!$C$5:$C$538,'Análise'!E$13) -> 0 | F18: =SUMIFS('Lançamentos'!$H$5:$H$538,'Lançamentos'!$D$5:$D$538,'Análise'!$B18,'Lançamentos'!$C$5:$C$538,'Análise'!F$13) -> 0 | G18: =SUMIFS('Lançamentos'!$H$5:$H$538,'Lançamentos'!$D$5:$D$538,'Análise'!$B18,'Lançamentos'!$C$5:$C$538,'Análise'!G$13) -> 2500 | H18: =SUMIFS('Lançamentos'!$H$5:$H$538,'Lançamentos'!$D$5:$D$538,'Análise'!$B18,'Lançamentos'!$C$5:$C$538,'Análise'!H$13) -> 2500 | I18: =SUMIFS('Lançamentos'!$H$5:$H$538,'Lançamentos'!$D$5:$D$538,'Análise'!$B18,'Lançamentos'!$C$5:$C$538,'Análise'!I$13) -> 2500 | J18: =SUMIFS('Lançamentos'!$H$5:$H$538,'Lançamentos'!$D$5:$D$538,'Análise'!$B18,'Lançamentos'!$C$5:$C$538,'Análise'!J$13) -> 2500 | ... P18: =SUMIFS('Lançamentos'!$H$5:$H$538,'Lançamentos'!$D$5:$D$538,'Análise'!$B18,'Lançamentos'!$C$5:$C$538,'Análise'!P$13) -> 0
B19: =Planilha1!B4 -> Amattheis Vogel | C19: =SUMIFS('Lançamentos'!$H$5:$H$538,'Lançamentos'!$D$5:$D$538,'Análise'!$B19,'Lançamentos'!$C$5:$C$538,'Análise'!C$13) -> 0 | D19: =SUMIFS('Lançamentos'!$H$5:$H$538,'Lançamentos'!$D$5:$D$538,'Análise'!$B19,'Lançamentos'!$C$5:$C$538,'Análise'!D$13) -> 0 | E19: =SUMIFS('Lançamentos'!$H$5:$H$538,'Lançamentos'!$D$5:$D$538,'Análise'!$B19,'Lançamentos'!$C$5:$C$538,'Análise'!E$13) -> 0 | F19: =SUMIFS('Lançamentos'!$H$5:$H$538,'Lançamentos'!$D$5:$D$538,'Análise'!$B19,'Lançamentos'!$C$5:$C$538,'Análise'!F$13) -> 0 | G19: =SUMIFS('Lançamentos'!$H$5:$H$538,'Lançamentos'!$D$5:$D$538,'Análise'!$B19,'Lançamentos'!$C$5:$C$538,'Análise'!G$13) -> 0 | H19: =SUMIFS('Lançamentos'!$H$5:$H$538,'Lançamentos'!$D$5:$D$538,'Análise'!$B19,'Lançamentos'!$C$5:$C$538,'Análise'!H$13) -> 6000 | I19: =SUMIFS('Lançamentos'!$H$5:$H$538,'Lançamentos'!$D$5:$D$538,'Análise'!$B19,'Lançamentos'!$C$5:$C$538,'Análise'!I$13) -> 5500 | J19: =SUMIFS('Lançamentos'!$H$5:$H$538,'Lançamentos'!$D$5:$D$538,'Análise'!$B19,'Lançamentos'!$C$5:$C$538,'Análise'!J$13) -> 5500 | ... P19: =SUMIFS('Lançamentos'!$H$5:$H$538,'Lançamentos'!$D$5:$D$538,'Análise'!$B19,'Lançamentos'!$C$5:$C$538,'Análise'!P$13) -> 0
B20: =Planilha1!B5 -> Eucomm Racing | C20: =SUMIFS('Lançamentos'!$H$5:$H$538,'Lançamentos'!$D$5:$D$538,'Análise'!$B20,'Lançamentos'!$C$5:$C$538,'Análise'!C$13) -> 0 | D20: =SUMIFS('Lançamentos'!$H$5:$H$538,'Lançamentos'!$D$5:$D$538,'Análise'!$B20,'Lançamentos'!$C$5:$C$538,'Análise'!D$13) -> 0 | E20: =SUMIFS('Lançamentos'!$H$5:$H$538,'Lançamentos'!$D$5:$D$538,'Análise'!$B20,'Lançamentos'!$C$5:$C$538,'Análise'!E$13) -> 0 | F20: =SUMIFS('Lançamentos'!$H$5:$H$538,'Lançamentos'!$D$5:$D$538,'Análise'!$B20,'Lançamentos'!$C$5:$C$538,'Análise'!F$13) -> 0 | G20: =SUMIFS('Lançamentos'!$H$5:$H$538,'Lançamentos'!$D$5:$D$538,'Análise'!$B20,'Lançamentos'!$C$5:$C$538,'Análise'!G$13) -> 0 | H20: =SUMIFS('Lançamentos'!$H$5:$H$538,'Lançamentos'!$D$5:$D$538,'Análise'!$B20,'Lançamentos'!$C$5:$C$538,'Análise'!H$13) -> 2500 | I20: =SUMIFS('Lançamentos'!$H$5:$H$538,'Lançamentos'!$D$5:$D$538,'Análise'!$B20,'Lançamentos'!$C$5:$C$538,'Análise'!I$13) -> 2500 | J20: =SUMIFS('Lançamentos'!$H$5:$H$538,'Lançamentos'!$D$5:$D$538,'Análise'!$B20,'Lançamentos'!$C$5:$C$538,'Análise'!J$13) -> 3700 | ... P20: =SUMIFS('Lançamentos'!$H$5:$H$538,'Lançamentos'!$D$5:$D$538,'Análise'!$B20,'Lançamentos'!$C$5:$C$538,'Análise'!P$13) -> 0
B21: =Planilha1!B6 -> CFA | C21: =SUMIFS('Lançamentos'!$H$5:$H$538,'Lançamentos'!$D$5:$D$538,'Análise'!$B21,'Lançamentos'!$C$5:$C$538,'Análise'!C$13) -> 0 | D21: =SUMIFS('Lançamentos'!$H$5:$H$538,'Lançamentos'!$D$5:$D$538,'Análise'!$B21,'Lançamentos'!$C$5:$C$538,'Análise'!D$13) -> 0 | E21: =SUMIFS('Lançamentos'!$H$5:$H$538,'Lançamentos'!$D$5:$D$538,'Análise'!$B21,'Lançamentos'!$C$5:$C$538,'Análise'!E$13) -> 0 | F21: =SUMIFS('Lançamentos'!$H$5:$H$538,'Lançamentos'!$D$5:$D$538,'Análise'!$B21,'Lançamentos'!$C$5:$C$538,'Análise'!F$13) -> 0 | G21: =SUMIFS('Lançamentos'!$H$5:$H$538,'Lançamentos'!$D$5:$D$538,'Análise'!$B21,'Lançamentos'!$C$5:$C$538,'Análise'!G$13) -> 1066 | H21: =SUMIFS('Lançamentos'!$H$5:$H$538,'Lançamentos'!$D$5:$D$538,'Análise'!$B21,'Lançamentos'!$C$5:$C$538,'Análise'!H$13) -> 0 | I21: =SUMIFS('Lançamentos'!$H$5:$H$538,'Lançamentos'!$D$5:$D$538,'Análise'!$B21,'Lançamentos'!$C$5:$C$538,'Análise'!I$13) -> 1066 | J21: =SUMIFS('Lançamentos'!$H$5:$H$538,'Lançamentos'!$D$5:$D$538,'Análise'!$B21,'Lançamentos'!$C$5:$C$538,'Análise'!J$13) -> 0 | ... P21: =SUMIFS('Lançamentos'!$H$5:$H$538,'Lançamentos'!$D$5:$D$538,'Análise'!$B21,'Lançamentos'!$C$5:$C$538,'Análise'!P$13) -> 0
B22: =Planilha1!B7 -> Kaka Magno | C22: =SUMIFS('Lançamentos'!$H$5:$H$538,'Lançamentos'!$D$5:$D$538,'Análise'!$B22,'Lançamentos'!$C$5:$C$538,'Análise'!C$13) -> 0 | D22: =SUMIFS('Lançamentos'!$H$5:$H$538,'Lançamentos'!$D$5:$D$538,'Análise'!$B22,'Lançamentos'!$C$5:$C$538,'Análise'!D$13) -> 0 | E22: =SUMIFS('Lançamentos'!$H$5:$H$538,'Lançamentos'!$D$5:$D$538,'Análise'!$B22,'Lançamentos'!$C$5:$C$538,'Análise'!E$13) -> 0 | F22: =SUMIFS('Lançamentos'!$H$5:$H$538,'Lançamentos'!$D$5:$D$538,'Análise'!$B22,'Lançamentos'!$C$5:$C$538,'Análise'!F$13) -> 0 | G22: =SUMIFS('Lançamentos'!$H$5:$H$538,'Lançamentos'!$D$5:$D$538,'Análise'!$B22,'Lançamentos'!$C$5:$C$538,'Análise'!G$13) -> 0 | H22: =SUMIFS('Lançamentos'!$H$5:$H$538,'Lançamentos'!$D$5:$D$538,'Análise'!$B22,'Lançamentos'!$C$5:$C$538,'Análise'!H$13) -> 1500 | I22: =SUMIFS('Lançamentos'!$H$5:$H$538,'Lançamentos'!$D$5:$D$538,'Análise'!$B22,'Lançamentos'!$C$5:$C$538,'Análise'!I$13) -> 1400 | J22: =SUMIFS('Lançamentos'!$H$5:$H$538,'Lançamentos'!$D$5:$D$538,'Análise'!$B22,'Lançamentos'!$C$5:$C$538,'Análise'!J$13) -> 570 | ... P22: =SUMIFS('Lançamentos'!$H$5:$H$538,'Lançamentos'!$D$5:$D$538,'Análise'!$B22,'Lançamentos'!$C$5:$C$538,'Análise'!P$13) -> 0
B23: =Planilha1!B8 -> Cadu Campos | C23: =SUMIFS('Lançamentos'!$H$5:$H$538,'Lançamentos'!$D$5:$D$538,'Análise'!$B23,'Lançamentos'!$C$5:$C$538,'Análise'!C$13) -> 0 | D23: =SUMIFS('Lançamentos'!$H$5:$H$538,'Lançamentos'!$D$5:$D$538,'Análise'!$B23,'Lançamentos'!$C$5:$C$538,'Análise'!D$13) -> 0 | E23: =SUMIFS('Lançamentos'!$H$5:$H$538,'Lançamentos'!$D$5:$D$538,'Análise'!$B23,'Lançamentos'!$C$5:$C$538,'Análise'!E$13) -> 0 | F23: =SUMIFS('Lançamentos'!$H$5:$H$538,'Lançamentos'!$D$5:$D$538,'Análise'!$B23,'Lançamentos'!$C$5:$C$538,'Análise'!F$13) -> 0 | G23: =SUMIFS('Lançamentos'!$H$5:$H$538,'Lançamentos'!$D$5:$D$538,'Análise'!$B23,'Lançamentos'!$C$5:$C$538,'Análise'!G$13) -> 0 | H23: =SUMIFS('Lançamentos'!$H$5:$H$538,'Lançamentos'!$D$5:$D$538,'Análise'!$B23,'Lançamentos'!$C$5:$C$538,'Análise'!H$13) -> 2460 | I23: =SUMIFS('Lançamentos'!$H$5:$H$538,'Lançamentos'!$D$5:$D$538,'Análise'!$B23,'Lançamentos'!$C$5:$C$538,'Análise'!I$13) -> 2105 | J23: =SUMIFS('Lançamentos'!$H$5:$H$538,'Lançamentos'!$D$5:$D$538,'Análise'!$B23,'Lançamentos'!$C$5:$C$538,'Análise'!J$13) -> 2100 | ... P23: =SUMIFS('Lançamentos'!$H$5:$H$538,'Lançamentos'!$D$5:$D$538,'Análise'!$B23,'Lançamentos'!$C$5:$C$538,'Análise'!P$13) -> 0
B24: =Planilha1!B9 -> Piloto TN - Paulo Maia | C24: =SUMIFS('Lançamentos'!$H$5:$H$538,'Lançamentos'!$D$5:$D$538,'Análise'!$B24,'Lançamentos'!$C$5:$C$538,'Análise'!C$13) -> 0 | D24: =SUMIFS('Lançamentos'!$H$5:$H$538,'Lançamentos'!$D$5:$D$538,'Análise'!$B24,'Lançamentos'!$C$5:$C$538,'Análise'!D$13) -> 0 | E24: =SUMIFS('Lançamentos'!$H$5:$H$538,'Lançamentos'!$D$5:$D$538,'Análise'!$B24,'Lançamentos'!$C$5:$C$538,'Análise'!E$13) -> 0 | F24: =SUMIFS('Lançamentos'!$H$5:$H$538,'Lançamentos'!$D$5:$D$538,'Análise'!$B24,'Lançamentos'!$C$5:$C$538,'Análise'!F$13) -> 0 | G24: =SUMIFS('Lançamentos'!$H$5:$H$538,'Lançamentos'!$D$5:$D$538,'Análise'!$B24,'Lançamentos'!$C$5:$C$538,'Análise'!G$13) -> 1800 | H24: =SUMIFS('Lançamentos'!$H$5:$H$538,'Lançamentos'!$D$5:$D$538,'Análise'!$B24,'Lançamentos'!$C$5:$C$538,'Análise'!H$13) -> 0 | I24: =SUMIFS('Lançamentos'!$H$5:$H$538,'Lançamentos'!$D$5:$D$538,'Análise'!$B24,'Lançamentos'!$C$5:$C$538,'Análise'!I$13) -> 3600 | J24: =SUMIFS('Lançamentos'!$H$5:$H$538,'Lançamentos'!$D$5:$D$538,'Análise'!$B24,'Lançamentos'!$C$5:$C$538,'Análise'!J$13) -> 0 | ... P24: =SUMIFS('Lançamentos'!$H$5:$H$538,'Lançamentos'!$D$5:$D$538,'Análise'!$B24,'Lançamentos'!$C$5:$C$538,'Análise'!P$13) -> 0
B25: =Planilha1!B10 -> Equipe TN - Porthack | C25: =SUMIFS('Lançamentos'!$H$5:$H$538,'Lançamentos'!$D$5:$D$538,'Análise'!$B25,'Lançamentos'!$C$5:$C$538,'Análise'!C$13) -> 0 | D25: =SUMIFS('Lançamentos'!$H$5:$H$538,'Lançamentos'!$D$5:$D$538,'Análise'!$B25,'Lançamentos'!$C$5:$C$538,'Análise'!D$13) -> 0 | E25: =SUMIFS('Lançamentos'!$H$5:$H$538,'Lançamentos'!$D$5:$D$538,'Análise'!$B25,'Lançamentos'!$C$5:$C$538,'Análise'!E$13) -> 0 | F25: =SUMIFS('Lançamentos'!$H$5:$H$538,'Lançamentos'!$D$5:$D$538,'Análise'!$B25,'Lançamentos'!$C$5:$C$538,'Análise'!F$13) -> 0 | G25: =SUMIFS('Lançamentos'!$H$5:$H$538,'Lançamentos'!$D$5:$D$538,'Análise'!$B25,'Lançamentos'!$C$5:$C$538,'Análise'!G$13) -> 1800 | H25: =SUMIFS('Lançamentos'!$H$5:$H$538,'Lançamentos'!$D$5:$D$538,'Análise'!$B25,'Lançamentos'!$C$5:$C$538,'Análise'!H$13) -> 0 | I25: =SUMIFS('Lançamentos'!$H$5:$H$538,'Lançamentos'!$D$5:$D$538,'Análise'!$B25,'Lançamentos'!$C$5:$C$538,'Análise'!I$13) -> 1800 | J25: =SUMIFS('Lançamentos'!$H$5:$H$538,'Lançamentos'!$D$5:$D$538,'Análise'!$B25,'Lançamentos'!$C$5:$C$538,'Análise'!J$13) -> 1800 | ... P25: =SUMIFS('Lançamentos'!$H$5:$H$538,'Lançamentos'!$D$5:$D$538,'Análise'!$B25,'Lançamentos'!$C$5:$C$538,'Análise'!P$13) -> 0
B26: =Planilha1!B11 -> Hublub | C26: =SUMIFS('Lançamentos'!$H$5:$H$538,'Lançamentos'!$D$5:$D$538,'Análise'!$B26,'Lançamentos'!$C$5:$C$538,'Análise'!C$13) -> 0 | D26: =SUMIFS('Lançamentos'!$H$5:$H$538,'Lançamentos'!$D$5:$D$538,'Análise'!$B26,'Lançamentos'!$C$5:$C$538,'Análise'!D$13) -> 0 | E26: =SUMIFS('Lançamentos'!$H$5:$H$538,'Lançamentos'!$D$5:$D$538,'Análise'!$B26,'Lançamentos'!$C$5:$C$538,'Análise'!E$13) -> 0 | F26: =SUMIFS('Lançamentos'!$H$5:$H$538,'Lançamentos'!$D$5:$D$538,'Análise'!$B26,'Lançamentos'!$C$5:$C$538,'Análise'!F$13) -> 0 | G26: =SUMIFS('Lançamentos'!$H$5:$H$538,'Lançamentos'!$D$5:$D$538,'Análise'!$B26,'Lançamentos'!$C$5:$C$538,'Análise'!G$13) -> 0 | H26: =SUMIFS('Lançamentos'!$H$5:$H$538,'Lançamentos'!$D$5:$D$538,'Análise'!$B26,'Lançamentos'!$C$5:$C$538,'Análise'!H$13) -> 4600 | I26: =SUMIFS('Lançamentos'!$H$5:$H$538,'Lançamentos'!$D$5:$D$538,'Análise'!$B26,'Lançamentos'!$C$5:$C$538,'Análise'!I$13) -> 4600 | J26: =SUMIFS('Lançamentos'!$H$5:$H$538,'Lançamentos'!$D$5:$D$538,'Análise'!$B26,'Lançamentos'!$C$5:$C$538,'Análise'!J$13) -> 4600 | ... P26: =SUMIFS('Lançamentos'!$H$5:$H$538,'Lançamentos'!$D$5:$D$538,'Análise'!$B26,'Lançamentos'!$C$5:$C$538,'Análise'!P$13) -> 0
B27: =Planilha1!B12 -> Silvana (Freela) | C27: =SUMIFS('Lançamentos'!$H$5:$H$538,'Lançamentos'!$D$5:$D$538,'Análise'!$B27,'Lançamentos'!$C$5:$C$538,'Análise'!C$13) -> 0 | D27: =SUMIFS('Lançamentos'!$H$5:$H$538,'Lançamentos'!$D$5:$D$538,'Análise'!$B27,'Lançamentos'!$C$5:$C$538,'Análise'!D$13) -> 500 | E27: =SUMIFS('Lançamentos'!$H$5:$H$538,'Lançamentos'!$D$5:$D$538,'Análise'!$B27,'Lançamentos'!$C$5:$C$538,'Análise'!E$13) -> 0 | F27: =SUMIFS('Lançamentos'!$H$5:$H$538,'Lançamentos'!$D$5:$D$538,'Análise'!$B27,'Lançamentos'!$C$5:$C$538,'Análise'!F$13) -> 0 | G27: =SUMIFS('Lançamentos'!$H$5:$H$538,'Lançamentos'!$D$5:$D$538,'Análise'!$B27,'Lançamentos'!$C$5:$C$538,'Análise'!G$13) -> 0 | H27: =SUMIFS('Lançamentos'!$H$5:$H$538,'Lançamentos'!$D$5:$D$538,'Análise'!$B27,'Lançamentos'!$C$5:$C$538,'Análise'!H$13) -> 250 | I27: =SUMIFS('Lançamentos'!$H$5:$H$538,'Lançamentos'!$D$5:$D$538,'Análise'!$B27,'Lançamentos'!$C$5:$C$538,'Análise'!I$13) -> 0 | J27: =SUMIFS('Lançamentos'!$H$5:$H$538,'Lançamentos'!$D$5:$D$538,'Análise'!$B27,'Lançamentos'!$C$5:$C$538,'Análise'!J$13) -> 0 | ... P27: =SUMIFS('Lançamentos'!$H$5:$H$538,'Lançamentos'!$D$5:$D$538,'Análise'!$B27,'Lançamentos'!$C$5:$C$538,'Análise'!P$13) -> 0
B28: =Planilha1!B13 -> Helio Castroneves | C28: =SUMIFS('Lançamentos'!$H$5:$H$538,'Lançamentos'!$D$5:$D$538,'Análise'!$B28,'Lançamentos'!$C$5:$C$538,'Análise'!C$13) -> 0 | D28: =SUMIFS('Lançamentos'!$H$5:$H$538,'Lançamentos'!$D$5:$D$538,'Análise'!$B28,'Lançamentos'!$C$5:$C$538,'Análise'!D$13) -> 0 | E28: =SUMIFS('Lançamentos'!$H$5:$H$538,'Lançamentos'!$D$5:$D$538,'Análise'!$B28,'Lançamentos'!$C$5:$C$538,'Análise'!E$13) -> 0 | F28: =SUMIFS('Lançamentos'!$H$5:$H$538,'Lançamentos'!$D$5:$D$538,'Análise'!$B28,'Lançamentos'!$C$5:$C$538,'Análise'!F$13) -> 0 | G28: =SUMIFS('Lançamentos'!$H$5:$H$538,'Lançamentos'!$D$5:$D$538,'Análise'!$B28,'Lançamentos'!$C$5:$C$538,'Análise'!G$13) -> 0 | H28: =SUMIFS('Lançamentos'!$H$5:$H$538,'Lançamentos'!$D$5:$D$538,'Análise'!$B28,'Lançamentos'!$C$5:$C$538,'Análise'!H$13) -> 0 | I28: =SUMIFS('Lançamentos'!$H$5:$H$538,'Lançamentos'!$D$5:$D$538,'Análise'!$B28,'Lançamentos'!$C$5:$C$538,'Análise'!I$13) -> 0 | J28: =SUMIFS('Lançamentos'!$H$5:$H$538,'Lançamentos'!$D$5:$D$538,'Análise'!$B28,'Lançamentos'!$C$5:$C$538,'Análise'!J$13) -> 0 | ... P28: =SUMIFS('Lançamentos'!$H$5:$H$538,'Lançamentos'!$D$5:$D$538,'Análise'!$B28,'Lançamentos'!$C$5:$C$538,'Análise'!P$13) -> 0
... B33: =Planilha1!B18 -> RMattheis | C33: =SUMIFS('Lançamentos'!$H$5:$H$538,'Lançamentos'!$D$5:$D$538,'Análise'!$B33,'Lançamentos'!$C$5:$C$538,'Análise'!C$13) -> 0 | D33: =SUMIFS('Lançamentos'!$H$5:$H$538,'Lançamentos'!$D$5:$D$538,'Análise'!$B33,'Lançamentos'!$C$5:$C$538,'Análise'!D$13) -> 0 | E33: =SUMIFS('Lançamentos'!$H$5:$H$538,'Lançamentos'!$D$5:$D$538,'Análise'!$B33,'Lançamentos'!$C$5:$C$538,'Análise'!E$13) -> 0 | F33: =SUMIFS('Lançamentos'!$H$5:$H$538,'Lançamentos'!$D$5:$D$538,'Análise'!$B33,'Lançamentos'!$C$5:$C$538,'Análise'!F$13) -> 0 | G33: =SUMIFS('Lançamentos'!$H$5:$H$538,'Lançamentos'!$D$5:$D$538,'Análise'!$B33,'Lançamentos'!$C$5:$C$538,'Análise'!G$13) -> 0 | H33: =SUMIFS('Lançamentos'!$H$5:$H$538,'Lançamentos'!$D$5:$D$538,'Análise'!$B33,'Lançamentos'!$C$5:$C$538,'Análise'!H$13) -> 0 | I33: =SUMIFS('Lançamentos'!$H$5:$H$538,'Lançamentos'!$D$5:$D$538,'Análise'!$B33,'Lançamentos'!$C$5:$C$538,'Análise'!I$13) -> 0 | J33: =SUMIFS('Lançamentos'!$H$5:$H$538,'Lançamentos'!$D$5:$D$538,'Análise'!$B33,'Lançamentos'!$C$5:$C$538,'Análise'!J$13) -> 0 | ... P33: =SUMIFS('Lançamentos'!$H$5:$H$538,'Lançamentos'!$D$5:$D$538,'Análise'!$B33,'Lançamentos'!$C$5:$C$538,'Análise'!P$13) -> 0
B34: Saídas | C34: =SUM(C35:C51) -> 705.82 | D34: =SUM(D35:D51) -> 0 | E34: =SUM(E35:E51) -> 2726 | F34: =SUM(F35:F51) -> 0 | G34: =SUM(G35:G51) -> 0 | H34: =SUM(H35:H51) -> 20441.19 | I34: =SUM(I35:I51) -> 18468.01 | J34: =SUM(J35:J51) -> 21585.48 | ... U34: =SUM(U35:U51) -> 0
B35: =Planilha1!B19 -> Salário Sócias | C35: =SUMIFS('Lançamentos'!$H$5:$H$538,'Lançamentos'!$D$5:$D$538,'Análise'!$B35,'Lançamentos'!$C$5:$C$538,'Análise'!C$13) -> 0 | D35: =SUMIFS('Lançamentos'!$H$5:$H$538,'Lançamentos'!$D$5:$D$538,'Análise'!$B35,'Lançamentos'!$C$5:$C$538,'Análise'!D$13) -> 0 | E35: =SUMIFS('Lançamentos'!$H$5:$H$538,'Lançamentos'!$D$5:$D$538,'Análise'!$B35,'Lançamentos'!$C$5:$C$538,'Análise'!E$13) -> 0 | F35: =SUMIFS('Lançamentos'!$H$5:$H$538,'Lançamentos'!$D$5:$D$538,'Análise'!$B35,'Lançamentos'!$C$5:$C$538,'Análise'!F$13) -> 0 | G35: =SUMIFS('Lançamentos'!$H$5:$H$538,'Lançamentos'!$D$5:$D$538,'Análise'!$B35,'Lançamentos'!$C$5:$C$538,'Análise'!G$13) -> 0 | H35: =SUMIFS('Lançamentos'!$H$5:$H$538,'Lançamentos'!$D$5:$D$538,'Análise'!$B35,'Lançamentos'!$C$5:$C$538,'Análise'!H$13) -> 14000 | I35: =SUMIFS('Lançamentos'!$H$5:$H$538,'Lançamentos'!$D$5:$D$538,'Análise'!$B35,'Lançamentos'!$C$5:$C$538,'Análise'!I$13) -> 14150 | J35: =SUMIFS('Lançamentos'!$H$5:$H$538,'Lançamentos'!$D$5:$D$538,'Análise'!$B35,'Lançamentos'!$C$5:$C$538,'Análise'!J$13) -> 13850 | ... P35: =SUMIFS('Lançamentos'!$H$5:$H$538,'Lançamentos'!$D$5:$D$538,'Análise'!$B35,'Lançamentos'!$C$5:$C$538,'Análise'!P$13) -> 0
B36: =Planilha1!B20 -> Locomoção etapas/Uber | C36: =SUMIFS('Lançamentos'!$H$5:$H$538,'Lançamentos'!$D$5:$D$538,'Análise'!$B36,'Lançamentos'!$C$5:$C$538,'Análise'!C$13) -> 0 | D36: =SUMIFS('Lançamentos'!$H$5:$H$538,'Lançamentos'!$D$5:$D$538,'Análise'!$B36,'Lançamentos'!$C$5:$C$538,'Análise'!D$13) -> 0 | E36: =SUMIFS('Lançamentos'!$H$5:$H$538,'Lançamentos'!$D$5:$D$538,'Análise'!$B36,'Lançamentos'!$C$5:$C$538,'Análise'!E$13) -> 0 | F36: =SUMIFS('Lançamentos'!$H$5:$H$538,'Lançamentos'!$D$5:$D$538,'Análise'!$B36,'Lançamentos'!$C$5:$C$538,'Análise'!F$13) -> 0 | G36: =SUMIFS('Lançamentos'!$H$5:$H$538,'Lançamentos'!$D$5:$D$538,'Análise'!$B36,'Lançamentos'!$C$5:$C$538,'Análise'!G$13) -> 0 | H36: =SUMIFS('Lançamentos'!$H$5:$H$538,'Lançamentos'!$D$5:$D$538,'Análise'!$B36,'Lançamentos'!$C$5:$C$538,'Análise'!H$13) -> 0 | I36: =SUMIFS('Lançamentos'!$H$5:$H$538,'Lançamentos'!$D$5:$D$538,'Análise'!$B36,'Lançamentos'!$C$5:$C$538,'Análise'!I$13) -> 0 | J36: =SUMIFS('Lançamentos'!$H$5:$H$538,'Lançamentos'!$D$5:$D$538,'Análise'!$B36,'Lançamentos'!$C$5:$C$538,'Análise'!J$13) -> 300.05 | ... P36: =SUMIFS('Lançamentos'!$H$5:$H$538,'Lançamentos'!$D$5:$D$538,'Análise'!$B36,'Lançamentos'!$C$5:$C$538,'Análise'!P$13) -> 0
B37: =Planilha1!B21 -> Designer | C37: =SUMIFS('Lançamentos'!$H$5:$H$538,'Lançamentos'!$D$5:$D$538,'Análise'!$B37,'Lançamentos'!$C$5:$C$538,'Análise'!C$13) -> 0 | D37: =SUMIFS('Lançamentos'!$H$5:$H$538,'Lançamentos'!$D$5:$D$538,'Análise'!$B37,'Lançamentos'!$C$5:$C$538,'Análise'!D$13) -> 0 | E37: =SUMIFS('Lançamentos'!$H$5:$H$538,'Lançamentos'!$D$5:$D$538,'Análise'!$B37,'Lançamentos'!$C$5:$C$538,'Análise'!E$13) -> 0 | F37: =SUMIFS('Lançamentos'!$H$5:$H$538,'Lançamentos'!$D$5:$D$538,'Análise'!$B37,'Lançamentos'!$C$5:$C$538,'Análise'!F$13) -> 0 | G37: =SUMIFS('Lançamentos'!$H$5:$H$538,'Lançamentos'!$D$5:$D$538,'Análise'!$B37,'Lançamentos'!$C$5:$C$538,'Análise'!G$13) -> 0 | H37: =SUMIFS('Lançamentos'!$H$5:$H$538,'Lançamentos'!$D$5:$D$538,'Análise'!$B37,'Lançamentos'!$C$5:$C$538,'Análise'!H$13) -> 200 | I37: =SUMIFS('Lançamentos'!$H$5:$H$538,'Lançamentos'!$D$5:$D$538,'Análise'!$B37,'Lançamentos'!$C$5:$C$538,'Análise'!I$13) -> 940 | J37: =SUMIFS('Lançamentos'!$H$5:$H$538,'Lançamentos'!$D$5:$D$538,'Análise'!$B37,'Lançamentos'!$C$5:$C$538,'Análise'!J$13) -> 640 | ... P37: =SUMIFS('Lançamentos'!$H$5:$H$538,'Lançamentos'!$D$5:$D$538,'Análise'!$B37,'Lançamentos'!$C$5:$C$538,'Análise'!P$13) -> 0
B38: =Planilha1!B22 -> Poupança - meses sem corrida | C38: =SUMIFS('Lançamentos'!$H$5:$H$538,'Lançamentos'!$D$5:$D$538,'Análise'!$B38,'Lançamentos'!$C$5:$C$538,'Análise'!C$13) -> 0 | D38: =SUMIFS('Lançamentos'!$H$5:$H$538,'Lançamentos'!$D$5:$D$538,'Análise'!$B38,'Lançamentos'!$C$5:$C$538,'Análise'!D$13) -> 0 | E38: =SUMIFS('Lançamentos'!$H$5:$H$538,'Lançamentos'!$D$5:$D$538,'Análise'!$B38,'Lançamentos'!$C$5:$C$538,'Análise'!E$13) -> 0 | F38: =SUMIFS('Lançamentos'!$H$5:$H$538,'Lançamentos'!$D$5:$D$538,'Análise'!$B38,'Lançamentos'!$C$5:$C$538,'Análise'!F$13) -> 0 | G38: =SUMIFS('Lançamentos'!$H$5:$H$538,'Lançamentos'!$D$5:$D$538,'Análise'!$B38,'Lançamentos'!$C$5:$C$538,'Análise'!G$13) -> 0 | H38: =SUMIFS('Lançamentos'!$H$5:$H$538,'Lançamentos'!$D$5:$D$538,'Análise'!$B38,'Lançamentos'!$C$5:$C$538,'Análise'!H$13) -> 0 | I38: =SUMIFS('Lançamentos'!$H$5:$H$538,'Lançamentos'!$D$5:$D$538,'Análise'!$B38,'Lançamentos'!$C$5:$C$538,'Análise'!I$13) -> 0 | J38: =SUMIFS('Lançamentos'!$H$5:$H$538,'Lançamentos'!$D$5:$D$538,'Análise'!$B38,'Lançamentos'!$C$5:$C$538,'Análise'!J$13) -> 3600 | ... P38: =SUMIFS('Lançamentos'!$H$5:$H$538,'Lançamentos'!$D$5:$D$538,'Análise'!$B38,'Lançamentos'!$C$5:$C$538,'Análise'!P$13) -> 0
B39: =Planilha1!B23 -> Impostos | C39: =SUMIFS('Lançamentos'!$H$5:$H$538,'Lançamentos'!$D$5:$D$538,'Análise'!$B39,'Lançamentos'!$C$5:$C$538,'Análise'!C$13) -> 0 | D39: =SUMIFS('Lançamentos'!$H$5:$H$538,'Lançamentos'!$D$5:$D$538,'Análise'!$B39,'Lançamentos'!$C$5:$C$538,'Análise'!D$13) -> 0 | E39: =SUMIFS('Lançamentos'!$H$5:$H$538,'Lançamentos'!$D$5:$D$538,'Análise'!$B39,'Lançamentos'!$C$5:$C$538,'Análise'!E$13) -> 0 | F39: =SUMIFS('Lançamentos'!$H$5:$H$538,'Lançamentos'!$D$5:$D$538,'Análise'!$B39,'Lançamentos'!$C$5:$C$538,'Análise'!F$13) -> 0 | G39: =SUMIFS('Lançamentos'!$H$5:$H$538,'Lançamentos'!$D$5:$D$538,'Análise'!$B39,'Lançamentos'!$C$5:$C$538,'Análise'!G$13) -> 0 | H39: =SUMIFS('Lançamentos'!$H$5:$H$538,'Lançamentos'!$D$5:$D$538,'Análise'!$B39,'Lançamentos'!$C$5:$C$538,'Análise'!H$13) -> 0 | I39: =SUMIFS('Lançamentos'!$H$5:$H$538,'Lançamentos'!$D$5:$D$538,'Análise'!$B39,'Lançamentos'!$C$5:$C$538,'Análise'!I$13) -> 0 | J39: =SUMIFS('Lançamentos'!$H$5:$H$538,'Lançamentos'!$D$5:$D$538,'Análise'!$B39,'Lançamentos'!$C$5:$C$538,'Análise'!J$13) -> 0 | ... P39: =SUMIFS('Lançamentos'!$H$5:$H$538,'Lançamentos'!$D$5:$D$538,'Análise'!$B39,'Lançamentos'!$C$5:$C$538,'Análise'!P$13) -> 0
B40: =Planilha1!B24 -> Pagamento Freelas | C40: =SUMIFS('Lançamentos'!$H$5:$H$538,'Lançamentos'!$D$5:$D$538,'Análise'!$B40,'Lançamentos'!$C$5:$C$538,'Análise'!C$13) -> 0 | D40: =SUMIFS('Lançamentos'!$H$5:$H$538,'Lançamentos'!$D$5:$D$538,'Análise'!$B40,'Lançamentos'!$C$5:$C$538,'Análise'!D$13) -> 0 | E40: =SUMIFS('Lançamentos'!$H$5:$H$538,'Lançamentos'!$D$5:$D$538,'Análise'!$B40,'Lançamentos'!$C$5:$C$538,'Análise'!E$13) -> 0 | F40: =SUMIFS('Lançamentos'!$H$5:$H$538,'Lançamentos'!$D$5:$D$538,'Análise'!$B40,'Lançamentos'!$C$5:$C$538,'Análise'!F$13) -> 0 | G40: =SUMIFS('Lançamentos'!$H$5:$H$538,'Lançamentos'!$D$5:$D$538,'Análise'!$B40,'Lançamentos'!$C$5:$C$538,'Análise'!G$13) -> 0 | H40: =SUMIFS('Lançamentos'!$H$5:$H$538,'Lançamentos'!$D$5:$D$538,'Análise'!$B40,'Lançamentos'!$C$5:$C$538,'Análise'!H$13) -> 4320.18 | I40: =SUMIFS('Lançamentos'!$H$5:$H$538,'Lançamentos'!$D$5:$D$538,'Análise'!$B40,'Lançamentos'!$C$5:$C$538,'Análise'!I$13) -> 0 | J40: =SUMIFS('Lançamentos'!$H$5:$H$538,'Lançamentos'!$D$5:$D$538,'Análise'!$B40,'Lançamentos'!$C$5:$C$538,'Análise'!J$13) -> 1715 | ... P40: =SUMIFS('Lançamentos'!$H$5:$H$538,'Lançamentos'!$D$5:$D$538,'Análise'!$B40,'Lançamentos'!$C$5:$C$538,'Análise'!P$13) -> 0
B41: =Planilha1!B25 -> Reembolso sócias | C41: =SUMIFS('Lançamentos'!$H$5:$H$538,'Lançamentos'!$D$5:$D$538,'Análise'!$B41,'Lançamentos'!$C$5:$C$538,'Análise'!C$13) -> 0 | D41: =SUMIFS('Lançamentos'!$H$5:$H$538,'Lançamentos'!$D$5:$D$538,'Análise'!$B41,'Lançamentos'!$C$5:$C$538,'Análise'!D$13) -> 0 | E41: =SUMIFS('Lançamentos'!$H$5:$H$538,'Lançamentos'!$D$5:$D$538,'Análise'!$B41,'Lançamentos'!$C$5:$C$538,'Análise'!E$13) -> 0 | F41: =SUMIFS('Lançamentos'!$H$5:$H$538,'Lançamentos'!$D$5:$D$538,'Análise'!$B41,'Lançamentos'!$C$5:$C$538,'Análise'!F$13) -> 0 | G41: =SUMIFS('Lançamentos'!$H$5:$H$538,'Lançamentos'!$D$5:$D$538,'Análise'!$B41,'Lançamentos'!$C$5:$C$538,'Análise'!G$13) -> 0 | H41: =SUMIFS('Lançamentos'!$H$5:$H$538,'Lançamentos'!$D$5:$D$538,'Análise'!$B41,'Lançamentos'!$C$5:$C$538,'Análise'!H$13) -> 0 | I41: =SUMIFS('Lançamentos'!$H$5:$H$538,'Lançamentos'!$D$5:$D$538,'Análise'!$B41,'Lançamentos'!$C$5:$C$538,'Análise'!I$13) -> 61 | J41: =SUMIFS('Lançamentos'!$H$5:$H$538,'Lançamentos'!$D$5:$D$538,'Análise'!$B41,'Lançamentos'!$C$5:$C$538,'Análise'!J$13) -> 234.2 | ... P41: =SUMIFS('Lançamentos'!$H$5:$H$538,'Lançamentos'!$D$5:$D$538,'Análise'!$B41,'Lançamentos'!$C$5:$C$538,'Análise'!P$13) -> 0
B42: =Planilha1!B26 -> Contador | C42: =SUMIFS('Lançamentos'!$H$5:$H$538,'Lançamentos'!$D$5:$D$538,'Análise'!$B42,'Lançamentos'!$C$5:$C$538,'Análise'!C$13) -> 0 | D42: =SUMIFS('Lançamentos'!$H$5:$H$538,'Lançamentos'!$D$5:$D$538,'Análise'!$B42,'Lançamentos'!$C$5:$C$538,'Análise'!D$13) -> 0 | E42: =SUMIFS('Lançamentos'!$H$5:$H$538,'Lançamentos'!$D$5:$D$538,'Análise'!$B42,'Lançamentos'!$C$5:$C$538,'Análise'!E$13) -> 0 | F42: =SUMIFS('Lançamentos'!$H$5:$H$538,'Lançamentos'!$D$5:$D$538,'Análise'!$B42,'Lançamentos'!$C$5:$C$538,'Análise'!F$13) -> 0 | G42: =SUMIFS('Lançamentos'!$H$5:$H$538,'Lançamentos'!$D$5:$D$538,'Análise'!$B42,'Lançamentos'!$C$5:$C$538,'Análise'!G$13) -> 0 | H42: =SUMIFS('Lançamentos'!$H$5:$H$538,'Lançamentos'!$D$5:$D$538,'Análise'!$B42,'Lançamentos'!$C$5:$C$538,'Análise'!H$13) -> 0 | I42: =SUMIFS('Lançamentos'!$H$5:$H$538,'Lançamentos'!$D$5:$D$538,'Análise'!$B42,'Lançamentos'!$C$5:$C$538,'Análise'!I$13) -> 0 | J42: =SUMIFS('Lançamentos'!$H$5:$H$538,'Lançamentos'!$D$5:$D$538,'Análise'!$B42,'Lançamentos'!$C$5:$C$538,'Análise'!J$13) -> 0 | ... P42: =SUMIFS('Lançamentos'!$H$5:$H$538,'Lançamentos'!$D$5:$D$538,'Análise'!$B42,'Lançamentos'!$C$5:$C$538,'Análise'!P$13) -> 0
B43: =Planilha1!B27 -> Uniforme | C43: =SUMIFS('Lançamentos'!$H$5:$H$538,'Lançamentos'!$D$5:$D$538,'Análise'!$B43,'Lançamentos'!$C$5:$C$538,'Análise'!C$13) -> 705.82 | D43: =SUMIFS('Lançamentos'!$H$5:$H$538,'Lançamentos'!$D$5:$D$538,'Análise'!$B43,'Lançamentos'!$C$5:$C$538,'Análise'!D$13) -> 0 | E43: =SUMIFS('Lançamentos'!$H$5:$H$538,'Lançamentos'!$D$5:$D$538,'Análise'!$B43,'Lançamentos'!$C$5:$C$538,'Análise'!E$13) -> 0 | F43: =SUMIFS('Lançamentos'!$H$5:$H$538,'Lançamentos'!$D$5:$D$538,'Análise'!$B43,'Lançamentos'!$C$5:$C$538,'Análise'!F$13) -> 0 | G43: =SUMIFS('Lançamentos'!$H$5:$H$538,'Lançamentos'!$D$5:$D$538,'Análise'!$B43,'Lançamentos'!$C$5:$C$538,'Análise'!G$13) -> 0 | H43: =SUMIFS('Lançamentos'!$H$5:$H$538,'Lançamentos'!$D$5:$D$538,'Análise'!$B43,'Lançamentos'!$C$5:$C$538,'Análise'!H$13) -> 0 | I43: =SUMIFS('Lançamentos'!$H$5:$H$538,'Lançamentos'!$D$5:$D$538,'Análise'!$B43,'Lançamentos'!$C$5:$C$538,'Análise'!I$13) -> 0 | J43: =SUMIFS('Lançamentos'!$H$5:$H$538,'Lançamentos'!$D$5:$D$538,'Análise'!$B43,'Lançamentos'!$C$5:$C$538,'Análise'!J$13) -> 0 | ... P43: =SUMIFS('Lançamentos'!$H$5:$H$538,'Lançamentos'!$D$5:$D$538,'Análise'!$B43,'Lançamentos'!$C$5:$C$538,'Análise'!P$13) -> 0
B44: =Planilha1!B28 -> Fotos/Estúdio | C44: =SUMIFS('Lançamentos'!$H$5:$H$538,'Lançamentos'!$D$5:$D$538,'Análise'!$B44,'Lançamentos'!$C$5:$C$538,'Análise'!C$13) -> 0 | D44: =SUMIFS('Lançamentos'!$H$5:$H$538,'Lançamentos'!$D$5:$D$538,'Análise'!$B44,'Lançamentos'!$C$5:$C$538,'Análise'!D$13) -> 0 | E44: =SUMIFS('Lançamentos'!$H$5:$H$538,'Lançamentos'!$D$5:$D$538,'Análise'!$B44,'Lançamentos'!$C$5:$C$538,'Análise'!E$13) -> 0 | F44: =SUMIFS('Lançamentos'!$H$5:$H$538,'Lançamentos'!$D$5:$D$538,'Análise'!$B44,'Lançamentos'!$C$5:$C$538,'Análise'!F$13) -> 0 | G44: =SUMIFS('Lançamentos'!$H$5:$H$538,'Lançamentos'!$D$5:$D$538,'Análise'!$B44,'Lançamentos'!$C$5:$C$538,'Análise'!G$13) -> 0 | H44: =SUMIFS('Lançamentos'!$H$5:$H$538,'Lançamentos'!$D$5:$D$538,'Análise'!$B44,'Lançamentos'!$C$5:$C$538,'Análise'!H$13) -> 0 | I44: =SUMIFS('Lançamentos'!$H$5:$H$538,'Lançamentos'!$D$5:$D$538,'Análise'!$B44,'Lançamentos'!$C$5:$C$538,'Análise'!I$13) -> 0 | J44: =SUMIFS('Lançamentos'!$H$5:$H$538,'Lançamentos'!$D$5:$D$538,'Análise'!$B44,'Lançamentos'!$C$5:$C$538,'Análise'!J$13) -> 0 | ... P44: =SUMIFS('Lançamentos'!$H$5:$H$538,'Lançamentos'!$D$5:$D$538,'Análise'!$B44,'Lançamentos'!$C$5:$C$538,'Análise'!P$13) -> 0
B45: =Planilha1!B29 -> Hospedagem | C45: =SUMIFS('Lançamentos'!$H$5:$H$538,'Lançamentos'!$D$5:$D$538,'Análise'!$B45,'Lançamentos'!$C$5:$C$538,'Análise'!C$13) -> 0 | D45: =SUMIFS('Lançamentos'!$H$5:$H$538,'Lançamentos'!$D$5:$D$538,'Análise'!$B45,'Lançamentos'!$C$5:$C$538,'Análise'!D$13) -> 0 | E45: =SUMIFS('Lançamentos'!$H$5:$H$538,'Lançamentos'!$D$5:$D$538,'Análise'!$B45,'Lançamentos'!$C$5:$C$538,'Análise'!E$13) -> 1128 | F45: =SUMIFS('Lançamentos'!$H$5:$H$538,'Lançamentos'!$D$5:$D$538,'Análise'!$B45,'Lançamentos'!$C$5:$C$538,'Análise'!F$13) -> 0 | G45: =SUMIFS('Lançamentos'!$H$5:$H$538,'Lançamentos'!$D$5:$D$538,'Análise'!$B45,'Lançamentos'!$C$5:$C$538,'Análise'!G$13) -> 0 | H45: =SUMIFS('Lançamentos'!$H$5:$H$538,'Lançamentos'!$D$5:$D$538,'Análise'!$B45,'Lançamentos'!$C$5:$C$538,'Análise'!H$13) -> 0 | I45: =SUMIFS('Lançamentos'!$H$5:$H$538,'Lançamentos'!$D$5:$D$538,'Análise'!$B45,'Lançamentos'!$C$5:$C$538,'Análise'!I$13) -> 1062.05 | J45: =SUMIFS('Lançamentos'!$H$5:$H$538,'Lançamentos'!$D$5:$D$538,'Análise'!$B45,'Lançamentos'!$C$5:$C$538,'Análise'!J$13) -> 199.59 | ... P45: =SUMIFS('Lançamentos'!$H$5:$H$538,'Lançamentos'!$D$5:$D$538,'Análise'!$B45,'Lançamentos'!$C$5:$C$538,'Análise'!P$13) -> 0
B46: =Planilha1!B30 -> Avião/ônibus etapas | C46: =SUMIFS('Lançamentos'!$H$5:$H$538,'Lançamentos'!$D$5:$D$538,'Análise'!$B46,'Lançamentos'!$C$5:$C$538,'Análise'!C$13) -> 0 | D46: =SUMIFS('Lançamentos'!$H$5:$H$538,'Lançamentos'!$D$5:$D$538,'Análise'!$B46,'Lançamentos'!$C$5:$C$538,'Análise'!D$13) -> 0 | E46: =SUMIFS('Lançamentos'!$H$5:$H$538,'Lançamentos'!$D$5:$D$538,'Análise'!$B46,'Lançamentos'!$C$5:$C$538,'Análise'!E$13) -> 1598 | F46: =SUMIFS('Lançamentos'!$H$5:$H$538,'Lançamentos'!$D$5:$D$538,'Análise'!$B46,'Lançamentos'!$C$5:$C$538,'Análise'!F$13) -> 0 | G46: =SUMIFS('Lançamentos'!$H$5:$H$538,'Lançamentos'!$D$5:$D$538,'Análise'!$B46,'Lançamentos'!$C$5:$C$538,'Análise'!G$13) -> 0 | H46: =SUMIFS('Lançamentos'!$H$5:$H$538,'Lançamentos'!$D$5:$D$538,'Análise'!$B46,'Lançamentos'!$C$5:$C$538,'Análise'!H$13) -> 1674.01 | I46: =SUMIFS('Lançamentos'!$H$5:$H$538,'Lançamentos'!$D$5:$D$538,'Análise'!$B46,'Lançamentos'!$C$5:$C$538,'Análise'!I$13) -> 1154 | J46: =SUMIFS('Lançamentos'!$H$5:$H$538,'Lançamentos'!$D$5:$D$538,'Análise'!$B46,'Lançamentos'!$C$5:$C$538,'Análise'!J$13) -> 360.69 | ... P46: =SUMIFS('Lançamentos'!$H$5:$H$538,'Lançamentos'!$D$5:$D$538,'Análise'!$B46,'Lançamentos'!$C$5:$C$538,'Análise'!P$13) -> 0
... B51: =Planilha1!B35 -> DAS Victoria | C51: =SUMIFS('Lançamentos'!$H$5:$H$538,'Lançamentos'!$D$5:$D$538,'Análise'!$B51,'Lançamentos'!$C$5:$C$538,'Análise'!C$13) -> 0 | D51: =SUMIFS('Lançamentos'!$H$5:$H$538,'Lançamentos'!$D$5:$D$538,'Análise'!$B51,'Lançamentos'!$C$5:$C$538,'Análise'!D$13) -> 0 | E51: =SUMIFS('Lançamentos'!$H$5:$H$538,'Lançamentos'!$D$5:$D$538,'Análise'!$B51,'Lançamentos'!$C$5:$C$538,'Análise'!E$13) -> 0 | F51: =SUMIFS('Lançamentos'!$H$5:$H$538,'Lançamentos'!$D$5:$D$538,'Análise'!$B51,'Lançamentos'!$C$5:$C$538,'Análise'!F$13) -> 0 | G51: =SUMIFS('Lançamentos'!$H$5:$H$538,'Lançamentos'!$D$5:$D$538,'Análise'!$B51,'Lançamentos'!$C$5:$C$538,'Análise'!G$13) -> 0 | H51: =SUMIFS('Lançamentos'!$H$5:$H$538,'Lançamentos'!$D$5:$D$538,'Análise'!$B51,'Lançamentos'!$C$5:$C$538,'Análise'!H$13) -> 0 | I51: =SUMIFS('Lançamentos'!$H$5:$H$538,'Lançamentos'!$D$5:$D$538,'Análise'!$B51,'Lançamentos'!$C$5:$C$538,'Análise'!I$13) -> 86.05 | J51: =SUMIFS('Lançamentos'!$H$5:$H$538,'Lançamentos'!$D$5:$D$538,'Análise'!$B51,'Lançamentos'!$C$5:$C$538,'Análise'!J$13) -> 86.05 | ... P51: =SUMIFS('Lançamentos'!$H$5:$H$538,'Lançamentos'!$D$5:$D$538,'Análise'!$B51,'Lançamentos'!$C$5:$C$538,'Análise'!P$13) -> 0
B52: Saldo Operacional | C52: =C16-C34 -> 1794.18 | D52: =D16-D34 -> 3000 | E52: =E16-E34 -> -2726 | F52: =F16-F34 -> 0 | G52: =G16-G34 -> 7166 | H52: =H16-H34 -> 568.81 | I52: =I16-I34 -> 7802.99 | J52: =J16-J34 -> 3082.52 | ... U52: =U16-U34 -> 0
B53: Saldo Acumulado | C53: =C15+C52 -> 1794.18 | D53: =D15+D52 -> 3000 | E53: =E15+E52 -> 274 | F53: =F15+F52 -> 274 | G53: =G15+G52 -> 7166 | H53: =H15+H52 -> 568.81 | I53: =I15+I52 -> 8409.8 | J53: =J15+J52 -> 3082.52 | ... U53: =U15+U52 -> 382.62

Sheet Gráficos
C6: ="Status: "&'Análise'!G7 -> Status: Todos
E43: Selecione a Conta para analisar:
E44: Eucomm Racing
E46: Valor Total
E47: =SUMIFS('Lançamentos'!$F$5:$F$538,'Lançamentos'!$D$5:$D$538,'Gráficos'!$E$44) -> 11200
E51: Valor Pago / Recebido
E52: =SUMIFS('Lançamentos'!$F$5:$F$538,'Lançamentos'!$G$5:$G$538,TRUE,'Lançamentos'!$D$5:$D$538,'Gráficos'!$E$44) -> 5000
E56: Valor Em Aberto
E57: =SUMIFS('Lançamentos'!$F$5:$F$538,'Lançamentos'!$G$5:$G$538,FALSE,'Lançamentos'!$D$5:$D$538,'Gráficos'!$E$44) -> 6200
